Workbook

Sheet 0320
A1: Country name | B1: city name | C1: Population | D1: Population density | E1: administrative area (km2) | F1: GDP per capita (2024/$) | G1: Total GDP (2024) | H1: GRDP / PDRB (2024) | I1: Vehicle quantity | J1: motor vehicles per 1,000 people | K1: Road network supply | L1: road length (km) | M1: Population density (persons/km)
A2: Indonesia | B2: Bandung | C2: 2528160 | D2: 15110.6 | E2: 167.31 | F2: 9580 | G2: $24.2 B | H2: 24.22 | I2: ~1,650,000 | J2: 652 | K2: 7.35 | L2: 1235.4 | M2: 2046
A3: Indonesia | B3: Jakarta | C3: 11010514 | D3: 16623.9 | E3: 662.33 | F3: 21350 | G3: $234.6 B | H3: 240.69 | I3: ~18,500,000 | J3: 1680 | K3: 10.42 | L3: 6952.1 | M3: 1583
A4: Indonesia | B4: Medan | C4: 2486283 | D4: 8816.9 | E4: 281.99 | F4: 7670 | G4: $20.5 B | H4: 20.98 | I4: ~1,420,000 | J4: 571 | K4: 11.24 | L4: 3178.6 | M4: 782
A5: Indonesia | B5: Palembang | C5: 1801367 | D5: 5110 | E5: 353 | F5: 7720 | G5: $13.3 B | H5: 14 | I5: ~980,000 | J5: 544 | K5: 5 | L5: 1722 | M5: 1046
A6: Indonesia | B6: Surabaya | C6: 3018022 | D6: 8927.7 | E6: 338.05 | F6: 16450 | G6: $50.0 B | H6: 51.24 | I6: ~2,850,000 | J6: 944 | K6: 6.51 | L6: 2208.5 | M6: 1366
A7: Malaysia | B7: George Town | C7: 794313 | D7: 2595.8 | E7: 306 | F7: 32850 | G7: $26.1 B | H7: 115.3 | I7: ~1,150,000 | J7: 1447 | K7: 7.19 | L7: 1155 | M7: 687
A8: Malaysia | B8: Ipoh | C8: 759952 | D8: 1181.9 | E8: 643 | F8: 24340 | G8: $18.5 B | H8: 81.7 | I8: ~880,000 | J8: 1158 | K8: 3.42 | L8: 2216 | M8: 342
A9: Malaysia | B9: Johor Bahru | C9: 858118 | D9: 2300 | E9: 373 | F9: 39600 | G9: $34.0 B | H9: 149.6 | I9: ~1,450,000 | J9: 1689 | K9: 5 | L9: 1845 | M9: 465
A10: Malaysia | B10: Kajang | C10: 1047356 | D10: 1330.8 | E10: 787 | F10: 13560 | G10: $14.2 B | H10: 62.5 | I10: ~1,750,000 | J10: 1671 | K10: 3.94 | L10: 3120 | M10: 335
A11: Malaysia | B11: Kota Bharu | C11: 568900 | D11: 4947 | E11: 115 | F11: 10810 | G11: $6.2 B | H11: 27.3 | I11: ~460,000 | J11: 808 | K11: 5.22 | L11: 625 | M11: 910
A12: Malaysia | B12: Kuala Lumpur | C12: 2075600 | D12: 8541.6 | E12: 243 | F12: 34200 | G12: $71.0 B | H12: 312.4 | I12: ~3,350,000 | J12: 1614 | K12: 14.81 | L12: 3654 | M12: 568
A13: Malaysia | B13: Seberang Perai | C13: 946092 | D13: 1265 | E13: 748 | F13: 27500 | G13: $26.1 B | H13: 114.8 | I13: ~1,250,000 | J13: 1321 | K13: 4 | L13: 3380 | M13: 279
... A23: Vietnam | B23: Ho Chi Minh | C23: 8899866 | D23: 4317.8 | E23: 2061.2 | F23: 7580 | G23: $69.4 B | H23: 1640 | I23: ~9,300,000 | J23: 1045 | K23: 2.14 | L23: 4420 | M23: 2013

Sheet data
A1: Country name | B1: city name | C1: Population | D1: Population density | E1: administrative area | F1: GDP per capita（2024/$ | G1: Total GDP（2024） | H1: GRDP / PDRB (2024) | I1: Vehicle quantity | J1: motor vehicles per 1,000 people | K1: Road network supply | L1: road length | M1: Population density (persons/km)
A2: Indonesia | B2: Bandung | C2: 2528160 | D2: 15110.6 | E2: 167.31 | F2: 9580 | G2: $24.2 B | H2: 24.22 | I2: ~1,650,000 | J2: 652 | K2: 7.35 | L2: 1235.4 | M2: 15110.6
A3: Indonesia | B3: Jakarta | C3: 11010514 | D3: 16623.9 | E3: 662.33 | F3: 21350 | G3: $234.6 B | H3: 240.69 | I3: ~21,800,000 | J3: 1979 | K3: 10.42 | L3: 6952.1 | M3: 16623.9
A4: Indonesia | B4: Medan | C4: 2486283 | D4: 8816.9 | E4: 281.99 | F4: 7670 | G4: $20.5 B | H4: 20.98 | I4: ~1,420,000 | J4: 571 | K4: 11.24 | L4: 3178.6 | M4: 8816.9
A5: Indonesia | B5: Palembang | C5: 1801367 | D5: 5110.1 | E5: 352.51 | F5: 7720 | G5: $13.3 B | H5: 13.58 | I5: ~980,000 | J5: 544 | K5: 4.88 | L5: 1722 | M5: 5110.1
A6: Indonesia | B6: Surabaya | C6: 3018022 | D6: 8927.7 | E6: 338.05 | F6: 16450 | G6: $50.0 B | H6: 51.24 | I6: ~2,850,000 | J6: 944 | K6: 6.51 | L6: 2208.5 | M6: 8927.7
A7: Malaysia | B7: George Town | C7: 794313 | D7: 2595.8 | E7: 306 | F7: 15420 | G7: $26.1 B | H7: 26.13 | I7: ~1,150,000 | J7: 1447 | K7: 7.19 | L7: 1155 | M7: 2595.8
A8: Malaysia | B8: Ipoh | C8: 759952 | D8: 1181.9 | E8: 643 | F8: 7460 | G8: $18.5 B | H8: 18.54 | I8: ~880,000 | J8: 1158 | K8: 3.42 | L8: 2216 | M8: 1181.9
A9: Malaysia | B9: Johor Bahru | C9: 858118 | D9: 2299.5 | E9: 373.18 | F9: 8520 | G9: $34.0 B | H9: 33.98 | I9: ~1,450,000 | J9: 1689 | K9: 4.82 | L9: 1845 | M9: 2299.5
A10: Malaysia | B10: Kajang | C10: 1047356 | D10: 1330.8 | E10: 787 | F10: 13560 | G10: $92.8 B | H10: 92.84 | I10: ~1,750,000 | J10: 1671 | K10: 3.94 | L10: 3120 | M10: 1330.8
A11: Malaysia | B11: Kota Bharu | C11: 568900 | D11: 4947 | E11: 115 | F11: 3610 | G11: $6.2 B | H11: 6.17 | I11: ~460,000 | J11: 808 | K11: 5.22 | L11: 625 | M11: 4947
A12: Malaysia | B12: Kuala Lumpur | C12: 2075600 | D12: 8541.6 | E12: 243 | F12: 29950 | G12: $57.0 B | H12: 56.95 | I12: ~3,350,000 | J12: 1614 | K12: 14.81 | L12: 3654 | M12: 8541.6
A13: Malaysia | B13: Seberang Perai | C13: 946092 | D13: 1264.8 | E13: 748 | F13: 15420 | G13: $26.1 B | H13: 26.13 | I13: ~1,250,000 | J13: 1321 | K13: 4.41 | L13: 3380 | M13: 1264.8
A14: Philippines | B14: Davao City | C14: 1848947 | D14: 756.6 | E14: 2443.61 | F14: 4420 | G14: $10.0 B | H14: 10 | I14: ~420,000 | J14: 227 | K14: 0.61 | L14: 1520 | M14: 756.6
A15: Philippines | B15: Manila City | C15: 14942000 | D15: 24117 | E15: 619.57 | F15: 10800 | G15: $21.3 B | H15: 8.88 | I15: ~680,000 | J15: 241 | K15: 1.15 | L15: 5,230 km | M15: 2726
A16: Singapore | B16: Singapore | C16: 6111200 | D16: 8210.7 | E16: 744.3 | F16: 89400 | G16: $530.0 B | H16: 532.74 | I16: ~995,000 | J16: 163 | K16: 4.7 | L16: 3522 | M16: 8210.7
A17: Thailand | B17: Bangkok | C17: 10539000 | D17: 6718.1 | E17: 1568.74 | F17: 19300 | G17: $170.4 B | H17: 170.42 | I17: ~11,500,000 | J17: 1091 | K17: 3.06 | L17: 4850 | M17: 6718.1
A18: Thailand | B18: Chiang Mai | C18: 1198000 | D18: 2958 | E18: 405 | F18: 4580 | G18: $8.3 B | H18: 8.31 | I18: ~920,000 | J18: 768 | K18: 4.94 | L18: 2045 | M18: 2958
A19: Thailand | B19: Hat Yai | C19: 404044 | D19: 473.8 | E19: 852.8 | F19: 5550 | G19: $7.9 B | H19: 7.94 | I19: ~560,000 | J19: 1385 | K19: 1.88 | L19: 1655 | M19: 473.8
A20: Thailand | B20: Khon Kaen | C20: 412758 | D20: 432.9 | E20: 953.4 | F20: 4120 | G20: $7.1 B | H20: 7.1 | I20: ~520,000 | J20: 1259 | K20: 1.68 | L20: 1680 | M20: 432.9
A21: Thailand | B21: Nakhon Ratchasima | C21: 466098 | D21: 616.9 | E21: 755.6 | F21: 3850 | G21: $10.1 B | H21: 10.08 | I21: ~680,000 | J21: 1458 | K21: 1.59 | L21: 1288 | M21: 616.9
A22: Vietnam | B22: Ha Noi | C22: 8807523 | D22: 2622.4 | E22: 3358.6 | F22: 6450 | G22: $53.1 B | H22: 53.14 | I22: ~7,600,000 | J22: 863 | K22: 1.34 | L22: 4560 | M22: 2622.4
A23: Vietnam | B23: Ho Chi Minh | C23: 8899866 | D23: 4317.8 | E23: 2061.2 | F23: 7580 | G23: $69.4 B | H23: 69.42 | I23: ~9,300,000 | J23: 1045 | K23: 2.13 | L23: 4420 | M23: 4317.8

Sheet Summary_Wide
A1: Country name | B1: city name | C1: Population | D1: Population density | E1: urban area | F1: administrative area | G1: Road network length | H1: Road density | I1: Registered cars | J1: Motorcycle ownership | K1: Public transport supply | L1: Employment density | M1: job concentration | N1: GDP per capita | O1: Total GDP | P1: Public transport modal share | Q1: Latest reference year | R1: Coverage score | S1: Boundary / notes
A2: Indonesia | B2: Bandung | C2: 2528160 | D2: =IFERROR(C2/F2,"") -> 15110.633 | F2: 167.31 | Q2: 2024 | R2: =COUNT(C2:P2)/18 -> 0.16666667 | S2: Boundary: city proper.
A3: Indonesia | B3: Jakarta | C3: 11010514 | D3: =IFERROR(C3/F3,"") -> 16623.91 | F3: 662.33 | Q3: 2025 | R3: =COUNT(C3:P3)/18 -> 0.16666667 | S3: Boundary: special capital region / province-equivalent.
A4: Indonesia | B4: Medan | C4: 2486283 | D4: =IFERROR(C4/F4,"") -> 8816.919 | F4: 281.99 | Q4: 2024 | R4: =COUNT(C4:P4)/18 -> 0.16666667 | S4: Boundary: city proper.
A5: Indonesia | B5: Palembang | C5: 1801367 | D5: =IFERROR(C5/F5,"") -> 5110.116 | F5: 352.51 | Q5: 2024 | R5: =COUNT(C5:P5)/18 -> 0.16666667 | S5: Boundary: city proper.
A6: Indonesia | B6: Surabaya | C6: 3018022 | D6: =IFERROR(C6/F6,"") -> 8927.7385 | F6: 338.05 | Q6: 2025 | R6: =COUNT(C6:P6)/18 -> 0.16666667 | S6: Boundary: city proper.
A7: Malaysia | B7: George Town | C7: 794313 | D7: =IFERROR(C7/F7,"") -> 2595.7941 | F7: 306 | Q7: 2020 | R7: =COUNT(C7:P7)/18 -> 0.16666667 | S7: Boundary: city proper. Includes pre-2024 values where newer city-level series were not readily citable.
A8: Malaysia | B8: Ipoh | C8: 759952 | D8: =IFERROR(C8/F8,"") -> 1181.8849 | F8: 643 | Q8: 2020 | R8: =COUNT(C8:P8)/18 -> 0.16666667 | S8: Boundary: city proper. Includes pre-2024 values where newer city-level series were not readily citable.
A9: Malaysia | B9: Johor Bahru | C9: 858118 | D9: =IFERROR(C9/F9,"") -> 2299.4748 | F9: 373.18 | Q9: 2020 | R9: =COUNT(C9:P9)/18 -> 0.16666667 | S9: Boundary: city proper. Includes pre-2024 values where newer city-level series were not readily citable.
A10: Malaysia | B10: Kajang | C10: 1047356 | D10: =IFERROR(C10/F10,"") -> 1330.8208 | F10: 787 | Q10: 2020 | R10: =COUNT(C10:P10)/18 -> 0.16666667 | S10: Boundary: local authority area / municipal council area. Includes pre-2024 values where newer city-level series were not readily citable.
A11: Malaysia | B11: Kota Bharu | C11: 568900 | D11: =IFERROR(C11/F11,"") -> 4946.9565 | F11: 115 | Q11: 2022 | R11: =COUNT(C11:P11)/18 -> 0.16666667 | S11: Boundary: city / municipality (secondary source). Includes pre-2024 values where newer city-level series were not readily citable.
A12: Malaysia | B12: Kuala Lumpur | C12: 2075600 | D12: =IFERROR(C12/F12,"") -> 8541.5638 | F12: 243 | N12: =IFERROR(O12/C12,"") -> 128059.36 | O12: 265800000000 | Q12: 2024 | R12: =COUNT(C12:P12)/18 -> 0.27777778 | S12: Boundary: federal territory / city.
A13: Malaysia | B13: Seberang Perai | C13: 946092 | D13: =IFERROR(C13/F13,"") -> 1264.8289 | F13: 748 | Q13: 2020 | R13: =COUNT(C13:P13)/18 -> 0.16666667 | S13: Boundary: local authority area / city council area. Includes pre-2024 values where newer city-level series were not readily citable.
A14: Philippines | B14: Davao City | C14: 1848947 | D14: =IFERROR(C14/F14,"") -> 756.6457 | F14: 2443.61 | N14: =IFERROR(O14/C14,"") -> 310836.38 | O14: 574720000000 | Q14: 2024 | R14: =COUNT(C14:P14)/18 -> 0.27777778 | S14: Boundary: highly urbanized city.
A15: Philippines | B15: Manila | C15: 1902590 | D15: =IFERROR(C15/F15,"") -> 44935.994 | F15: 42.34 | N15: =IFERROR(O15/C15,"") -> 546623.29 | O15: 1040000000000 | Q15: 2024 | R15: =COUNT(C15:P15)/18 -> 0.27777778 | S15: Boundary: highly urbanized city.
A16: Singapore | B16: Singapore | C16: 6111200 | D16: =IFERROR(C16/F16,"") -> 8210.6677 | F16: 744.3 | N16: 121161 | O16: 765497500000 | Q16: 2025 | R16: =COUNT(C16:P16)/18 -> 0.27777778 | S16: Boundary: nation-city.
A17: Thailand | B17: Bangkok | C17: 10539000 | D17: =IFERROR(C17/F17,"") -> 6718.1305 | F17: 1568.74 | Q17: 2021 | R17: =COUNT(C17:P17)/18 -> 0.16666667 | S17: Boundary: urban area series (secondary). Includes pre-2024 values where newer city-level series were not readily citable.
A18: Thailand | B18: Chiang Mai | C18: 1198000 | D18: =IFERROR(C18/F18,"") -> 2958.0247 | F18: 405 | Q18: 2021 | R18: =COUNT(C18:P18)/18 -> 0.16666667 | S18: Boundary: urban area series (secondary). Includes pre-2024 values where newer city-level series were not readily citable.
A19: Thailand | B19: Hat Yai | C19: 404044 | D19: =IFERROR(C19/F19,"") -> 473.7874 | F19: 852.796 | Q19: 2021 | R19: =COUNT(C19:P19)/18 -> 0.16666667 | S19: Boundary: urban area series (secondary). Includes pre-2024 values where newer city-level series were not readily citable.
A20: Thailand | B20: Khon Kaen | C20: 412758 | D20: =IFERROR(C20/F20,"") -> 432.93266 | F20: 953.4 | Q20: 2021 | R20: =COUNT(C20:P20)/18 -> 0.16666667 | S20: Boundary: urban area series (secondary). Includes pre-2024 values where newer city-level series were not readily citable.
A21: Thailand | B21: Nakhon Ratchasima | C21: 466098 | D21: =IFERROR(C21/F21,"") -> 616.85813 | F21: 755.6 | Q21: 2021 | R21: =COUNT(C21:P21)/18 -> 0.16666667 | S21: Boundary: urban area series (secondary). Includes pre-2024 values where newer city-level series were not readily citable.
A22: Vietnam | B22: Ha Noi | C22: 8807523 | D22: =IFERROR(C22/F22,"") -> 2622.3793 | F22: 3358.6 | N22: 163500000 | O22: 1.43e+15 | Q22: 2025 | R22: =COUNT(C22:P22)/18 -> 0.27777778 | S22: Boundary: municipality / capital city.
A23: Vietnam | B23: Ho Chi Minh | C23: 8899866 | D23: =IFERROR(C23/F23,"") -> 4317.8081 | F23: 2061.2 | O23: 1.78e+15 | Q23: 2024 | R23: =COUNT(C23:P23)/18 -> 0.22222222 | S23: Boundary: municipality (pre-merger boundary unless noted). Includes pre-2024 values where newer city-level series were not readily citable.

Sheet Data_Long
A1: Country | B1: City | C1: Indicator | D1: Value | E1: Unit | F1: Reference year | G1: Source tier | H1: Source title | I1: Source URL | J1: Boundary / notes
A2: Indonesia | B2: Bandung | C2: Population | D2: 2528160 | E2: persons | F2: 2024 | G2: Secondary | H2: Bandung metropolitan area (Wikipedia search snippet citing official BPS mid-2024 estimate) | I2: https://en.wikipedia.org/wiki/Bandung_metropolitan_area | J2: city proper; Mid-2024 estimate; secondary source cites official BPS estimate.
A3: Indonesia | B3: Bandung | C3: Administrative area | D3: 167.31 | E3: km² | F3: 2024 | G3: Primary | H3: Area by Subdistrict in the City of Bandung (Km2), 2024 - BPS Bandung Municipality | I3: https://bandungkota.bps.go.id/en/statistics-table/2/MzQjMg%3D%3D/area-by-subdistrict-in-th-city-of-bandung.html | J3: city proper; BPS Bandung Municipality, total city area.
A4: Indonesia | B4: Bandung | C4: Population density | D4: =IFERROR(Summary_Wide!D2,"") -> 15110.633 | E4: persons/km² | F4: 2024 | G4: Derived | H4: Bandung metropolitan area (Wikipedia search snippet citing official BPS mid-2024 estimate) + Area by Subdistrict in the City of Bandung (Km2), 2024 - BPS Bandung Municipality | I4: https://en.wikipedia.org/wiki/Bandung_metropolitan_area | https://bandungkota.bps.go.id/en/statistics-table/2/MzQjMg%3D%3D/area-by-subdistrict-in-th-city-of-bandung.html | J4: city proper; Derived in workbook as Population / Administrative area.
A5: Indonesia | B5: Jakarta | C5: Population | D5: 11010514 | E5: persons | F5: 2025 | G5: Primary | H5: Jakarta population recorded at 11.01 million - Berita Jakarta | I5: https://m.beritajakarta.id/en/read/61194/jakarta-population-recorded-at-1101-million | J5: special capital region / province-equivalent; First semester 2025 population reported by Jakarta official media.
A6: Indonesia | B6: Jakarta | C6: Administrative area | D6: 662.33 | E6: km² | F6: 2025 | G6: Primary | H6: Tentang Jakarta - Pemerintah Provinsi DKI Jakarta | I6: https://www.jakarta.go.id/tentang-jakarta | J6: special capital region / province-equivalent; Land area reported by Jakarta provincial government.
A7: Indonesia | B7: Jakarta | C7: Population density | D7: =IFERROR(Summary_Wide!D3,"") -> 16623.91 | E7: persons/km² | F7: 2025 | G7: Derived | H7: Jakarta population recorded at 11.01 million - Berita Jakarta + Tentang Jakarta - Pemerintah Provinsi DKI Jakarta | I7: https://m.beritajakarta.id/en/read/61194/jakarta-population-recorded-at-1101-million | https://www.jakarta.go.id/tentang-jakarta | J7: special capital region / province-equivalent; Derived in workbook as Population / Administrative area.
A8: Indonesia | B8: Medan | C8: Population | D8: 2486283 | E8: persons | F8: 2024 | G8: Secondary | H8: Medan (Wikipedia search snippet citing BPS Kota Medan Dalam Angka 2025) | I8: https://en.wikipedia.org/wiki/Medan | J8: city proper; Official mid-2024 estimate cited in secondary source.
A9: Indonesia | B9: Medan | C9: Administrative area | D9: 281.99 | E9: km² | F9: 2024 | G9: Secondary | H9: Medan (Wikipedia search snippet citing BPS Kota Medan Dalam Angka 2025) | I9: https://en.wikipedia.org/wiki/Medan | J9: city proper; City area from BPS-cited secondary source.
A10: Indonesia | B10: Medan | C10: Population density | D10: =IFERROR(Summary_Wide!D4,"") -> 8816.919 | E10: persons/km² | F10: 2024 | G10: Derived | H10: Medan (Wikipedia search snippet citing BPS Kota Medan Dalam Angka 2025) + Medan (Wikipedia search snippet citing BPS Kota Medan Dalam Angka 2025) | I10: https://en.wikipedia.org/wiki/Medan | https://en.wikipedia.org/wiki/Medan | J10: city proper; Derived in workbook as Population / Administrative area.
A11: Indonesia | B11: Palembang | C11: Population | D11: 1801367 | E11: persons | F11: 2024 | G11: Secondary | H11: Palembang (Wikipedia search snippet citing official mid-2024 estimate) | I11: https://en.wikipedia.org/wiki/Palembang | J11: city proper; Official mid-2024 estimate cited in secondary source.
A12: Indonesia | B12: Palembang | C12: Administrative area | D12: 352.51 | E12: km² | F12: 2024 | G12: Primary | H12: Total Area by Regency/Municipality (Km2), 2024 - BPS Sumatera Selatan | I12: https://sumsel.bps.go.id/en/statistics-table/2/MjAxIzI%3D/luas-wilayah | J12: city proper; BPS Sumatera Selatan, 2024 area table.
A13: Indonesia | B13: Palembang | C13: Population density | D13: =IFERROR(Summary_Wide!D5,"") -> 5110.116 | E13: persons/km² | F13: 2024 | G13: Derived | H13: Palembang (Wikipedia search snippet citing official mid-2024 estimate) + Total Area by Regency/Municipality (Km2), 2024 - BPS Sumatera Selatan | I13: https://en.wikipedia.org/wiki/Palembang | https://sumsel.bps.go.id/en/statistics-table/2/MjAxIzI%3D/luas-wilayah | J13: city proper; Derived in workbook as Population / Administrative area.
A14: Indonesia | B14: Surabaya | C14: Population | D14: 3018022 | E14: persons | F14: 2024 | G14: Secondary | H14: Surabaya (Wikipedia search snippet citing official mid-2024 estimate) | I14: https://en.wikipedia.org/wiki/Surabaya | J14: city proper; Official mid-2024 estimate cited in secondary source.
A15: Indonesia | B15: Surabaya | C15: Administrative area | D15: 338.05 | E15: km² | F15: 2025 | G15: Primary | H15: Luas Daerah Menurut Kabupaten/Kota di Provinsi Jawa Timur, 2025 - BPS Jawa Timur | I15: https://jatim.bps.go.id/en/statistics-table/3/VUZwV01tSlpPVlpsWlRKbmMxcFhhSGhEVjFoUFFUMDkjMw%3D%3D/luas-daerah-dan-jumlah-pulau-menurut-kabupaten-kota-di-provinsi-jawa-timur--2024.html | J15: city proper; BPS Jawa Timur 2025 area table.
A16: Indonesia | B16: Surabaya | C16: Population density | D16: =IFERROR(Summary_Wide!D6,"") -> 8927.7385 | E16: persons/km² | F16: 2025 | G16: Derived | H16: Surabaya (Wikipedia search snippet citing official mid-2024 estimate) + Luas Daerah Menurut Kabupaten/Kota di Provinsi Jawa Timur, 2025 - BPS Jawa Timur | I16: https://en.wikipedia.org/wiki/Surabaya | https://jatim.bps.go.id/en/statistics-table/3/VUZwV01tSlpPVlpsWlRKbmMxcFhhSGhEVjFoUFFUMDkjMw%3D%3D/luas-daerah-dan-jumlah-pulau-menurut-kabupaten-kota-di-provinsi-jawa-timur--2024.html | J16: city proper; Derived in workbook as Population / Administrative area.
A17: Malaysia | B17: George Town | C17: Population | D17: 794313 | E17: persons | F17: 2020 | G17: Secondary | H17: George Town, Penang (Wikipedia; 2020 population and area) | I17: https://en.wikipedia.org/wiki/George_Town,_Penang | J17: city proper; 2020 city proper population.
A18: Malaysia | B18: George Town | C18: Administrative area | D18: 306 | E18: km² | F18: 2020 | G18: Secondary | H18: George Town, Penang (Wikipedia; 2020 population and area) | I18: https://en.wikipedia.org/wiki/George_Town,_Penang | J18: city proper; City proper area.
A19: Malaysia | B19: George Town | C19: Population density | D19: =IFERROR(Summary_Wide!D7,"") -> 2595.7941 | E19: persons/km² | F19: 2020 | G19: Derived | H19: George Town, Penang (Wikipedia; 2020 population and area) + George Town, Penang (Wikipedia; 2020 population and area) | I19: https://en.wikipedia.org/wiki/George_Town,_Penang | https://en.wikipedia.org/wiki/George_Town,_Penang | J19: city proper; Derived in workbook as Population / Administrative area.
A20: Malaysia | B20: Ipoh | C20: Population | D20: 759952 | E20: persons | F20: 2020 | G20: Secondary | H20: Ipoh (Wikipedia; 2020 population and area) | I20: https://en.wikipedia.org/wiki/Ipoh | J20: city proper; 2020 city population.
A21: Malaysia | B21: Ipoh | C21: Administrative area | D21: 643 | E21: km² | F21: 2020 | G21: Secondary | H21: Ipoh (Wikipedia; 2020 population and area) | I21: https://en.wikipedia.org/wiki/Ipoh | J21: city proper; City area.
A22: Malaysia | B22: Ipoh | C22: Population density | D22: =IFERROR(Summary_Wide!D8,"") -> 1181.8849 | E22: persons/km² | F22: 2020 | G22: Derived | H22: Ipoh (Wikipedia; 2020 population and area) + Ipoh (Wikipedia; 2020 population and area) | I22: https://en.wikipedia.org/wiki/Ipoh | https://en.wikipedia.org/wiki/Ipoh | J22: city proper; Derived in workbook as Population / Administrative area.
A23: Malaysia | B23: Johor Bahru | C23: Population | D23: 858118 | E23: persons | F23: 2020 | G23: Secondary | H23: Johor Bahru (Wikipedia; 2020 population and area) | I23: https://en.wikipedia.org/wiki/Johor_Bahru | J23: city proper; 2020 city proper population.
A24: Malaysia | B24: Johor Bahru | C24: Administrative area | D24: 373.18 | E24: km² | F24: 2020 | G24: Secondary | H24: Johor Bahru (Wikipedia; 2020 population and area) | I24: https://en.wikipedia.org/wiki/Johor_Bahru | J24: city proper; City proper area.
A25: Malaysia | B25: Johor Bahru | C25: Population density | D25: =IFERROR(Summary_Wide!D9,"") -> 2299.4748 | E25: persons/km² | F25: 2020 | G25: Derived | H25: Johor Bahru (Wikipedia; 2020 population and area) + Johor Bahru (Wikipedia; 2020 population and area) | I25: https://en.wikipedia.org/wiki/Johor_Bahru | https://en.wikipedia.org/wiki/Johor_Bahru | J25: city proper; Derived in workbook as Population / Administrative area.
A26: Malaysia | B26: Kajang | C26: Population | D26: 1047356 | E26: persons | F26: 2020 | G26: Primary | H26: Key Findings Population and Housing Census of Malaysia 2020: Administrative District - DOSM | I26: https://www.dosm.gov.my/portal-main/release-content/key-findings-population-and-housing-census-of-malaysia-2020-administrative-district | J26: local authority area / municipal council area; Kajang Municipal Council / local authority population from DOSM census release.
A27: Malaysia | B27: Kajang | C27: Administrative area | D27: 787 | E27: km² | F27: 2020 | G27: Secondary | H27: Kajang (Wikipedia; local authority area) | I27: https://en.wikipedia.org/wiki/Kajang | J27: local authority area / municipal council area; Local authority area from secondary source.
A28: Malaysia | B28: Kajang | C28: Population density | D28: =IFERROR(Summary_Wide!D10,"") -> 1330.8208 | E28: persons/km² | F28: 2020 | G28: Derived | H28: Key Findings Population and Housing Census of Malaysia 2020: Administrative District - DOSM + Kajang (Wikipedia; local authority area) | I28: https://www.dosm.gov.my/portal-main/release-content/key-findings-population-and-housing-census-of-malaysia-2020-administrative-district | https://en.wikipedia.org/wiki/Kajang | J28: local authority area / municipal council area; Derived in workbook as Population / Administrative area.
A29: Malaysia | B29: Kota Bharu | C29: Population | D29: 568900 | E29: persons | F29: 2022 | G29: Secondary | H29: Kota Bharu (Wikipedia / city summary) | I29: https://en.wikipedia.org/wiki/Kota_Bharu | J29: city / municipality (secondary source); Secondary source; city/municipality figure.
A30: Malaysia | B30: Kota Bharu | C30: Administrative area | D30: 115 | E30: km² | F30: 2022 | G30: Secondary | H30: Kota Bharu (Wikipedia / city summary) | I30: https://en.wikipedia.org/wiki/Kota_Bharu | J30: city / municipality (secondary source); Secondary source.
A31: Malaysia | B31: Kota Bharu | C31: Population density | D31: =IFERROR(Summary_Wide!D11,"") -> 4946.9565 | E31: persons/km² | F31: 2022 | G31: Derived | H31: Kota Bharu (Wikipedia / city summary) + Kota Bharu (Wikipedia / city summary) | I31: https://en.wikipedia.org/wiki/Kota_Bharu | https://en.wikipedia.org/wiki/Kota_Bharu | J31: city / municipality (secondary source); Derived in workbook as Population / Administrative area.
A32: Malaysia | B32: Kuala Lumpur | C32: Population | D32: 2075600 | E32: persons | F32: 2024 | G32: Primary | H32: W.P. Kuala Lumpur - The Population of Malaysia - OpenDOSM | I32: https://open.dosm.gov.my/dashboard/population/kul | J32: federal territory / city; OpenDOSM dashboard reports total population (2024) ~2.1 million.
A33: Malaysia | B33: Kuala Lumpur | C33: Administrative area | D33: 243 | E33: km² | F33: 2024 | G33: Secondary | H33: Kuala Lumpur (Wikipedia; area 243 km²) | I33: https://en.wikipedia.org/wiki/Kuala_Lumpur | J33: federal territory / city; Federal territory area.
A34: Malaysia | B34: Kuala Lumpur | C34: Total GDP | D34: 265800000000 | E34: RM | F34: 2024 | G34: Primary | H34: Media Statement Gross Domestic Product (GDP) by State 2024 - DOSM | I34: https://www.statistics.gov.my/uploads/release-content/file_20250701120035.pdf | J34: federal territory / city; DOSM GDP by state 2024; applied here to the Federal Territory of Kuala Lumpur.
A35: Malaysia | B35: Kuala Lumpur | C35: GDP per capita | D35: =IFERROR(Summary_Wide!N12,"") -> 128059.36 | E35: RM/person | F35: 2024 | G35: Derived | H35: Media Statement Gross Domestic Product (GDP) by State 2024 - DOSM + W.P. Kuala Lumpur - The Population of Malaysia - OpenDOSM | I35: https://www.statistics.gov.my/uploads/release-content/file_20250701120035.pdf | https://open.dosm.gov.my/dashboard/population/kul | J35: federal territory / city; Derived in workbook as Total GDP / Population. Underlying sources: Media Statement Gross Domestic Product (GDP) by State 2024 - DOSM | W.P. Kuala Lumpur - The Population of Malaysia - OpenDOSM. Derived in workbook from 2024 GDP ÷ 2024 population.
A36: Malaysia | B36: Kuala Lumpur | C36: Population density | D36: =IFERROR(Summary_Wide!D12,"") -> 8541.5638 | E36: persons/km² | F36: 2024 | G36: Derived | H36: W.P. Kuala Lumpur - The Population of Malaysia - OpenDOSM + Kuala Lumpur (Wikipedia; area 243 km²) | I36: https://open.dosm.gov.my/dashboard/population/kul | https://en.wikipedia.org/wiki/Kuala_Lumpur | J36: federal territory / city; Derived in workbook as Population / Administrative area.
A37: Malaysia | B37: Seberang Perai | C37: Population | D37: 946092 | E37: persons | F37: 2020 | G37: Primary | H37: Key Findings Population and Housing Census of Malaysia 2020: Administrative District - DOSM | I37: https://www.dosm.gov.my/portal-main/release-content/key-findings-population-and-housing-census-of-malaysia-2020-administrative-district | J37: local authority area / city council area; Seberang Perai City Council / local authority population from DOSM census release.
A38: Malaysia | B38: Seberang Perai | C38: Administrative area | D38: 748 | E38: km² | F38: 2020 | G38: Secondary | H38: Seberang Perai (Wikipedia; local authority area) | I38: https://en.wikipedia.org/wiki/Seberang_Perai | J38: local authority area / city council area; Local authority area.
A39: Malaysia | B39: Seberang Perai | C39: Population density | D39: =IFERROR(Summary_Wide!D13,"") -> 1264.8289 | E39: persons/km² | F39: 2020 | G39: Derived | H39: Key Findings Population and Housing Census of Malaysia 2020: Administrative District - DOSM + Seberang Perai (Wikipedia; local authority area) | I39: https://www.dosm.gov.my/portal-main/release-content/key-findings-population-and-housing-census-of-malaysia-2020-administrative-district | https://en.wikipedia.org/wiki/Seberang_Perai | J39: local authority area / city council area; Derived in workbook as Population / Administrative area.
A40: Philippines | B40: Davao City | C40: Population | D40: 1848947 | E40: persons | F40: 2024 | G40: Secondary | H40: Davao City (Wikipedia; 2024 census population and area) | I40: https://en.wikipedia.org/wiki/Davao_City | J40: highly urbanized city; 2024 census population in secondary source.
...

Sheet Source_Index
A1: Source ID | B1: Source tier | C1: Title | D1: URL
A2: bandung_pop | B2: Secondary | C2: Bandung metropolitan area (Wikipedia search snippet citing official BPS mid-2024 estimate) | D2: https://en.wikipedia.org/wiki/Bandung_metropolitan_area
A3: bandung_area | B3: Primary | C3: Area by Subdistrict in the City of Bandung (Km2), 2024 - BPS Bandung Municipality | D3: https://bandungkota.bps.go.id/en/statistics-table/2/MzQjMg%3D%3D/area-by-subdistrict-in-th-city-of-bandung.html
A4: jakarta_pop | B4: Primary | C4: Jakarta population recorded at 11.01 million - Berita Jakarta | D4: https://m.beritajakarta.id/en/read/61194/jakarta-population-recorded-at-1101-million
A5: jakarta_area | B5: Primary | C5: Tentang Jakarta - Pemerintah Provinsi DKI Jakarta | D5: https://www.jakarta.go.id/tentang-jakarta
A6: medan_poparea | B6: Secondary | C6: Medan (Wikipedia search snippet citing BPS Kota Medan Dalam Angka 2025) | D6: https://en.wikipedia.org/wiki/Medan
A7: palembang_pop | B7: Secondary | C7: Palembang (Wikipedia search snippet citing official mid-2024 estimate) | D7: https://en.wikipedia.org/wiki/Palembang
A8: palembang_area | B8: Primary | C8: Total Area by Regency/Municipality (Km2), 2024 - BPS Sumatera Selatan | D8: https://sumsel.bps.go.id/en/statistics-table/2/MjAxIzI%3D/luas-wilayah
A9: surabaya_pop | B9: Secondary | C9: Surabaya (Wikipedia search snippet citing official mid-2024 estimate) | D9: https://en.wikipedia.org/wiki/Surabaya
A10: surabaya_area | B10: Primary | C10: Luas Daerah Menurut Kabupaten/Kota di Provinsi Jawa Timur, 2025 - BPS Jawa Timur | D10: https://jatim.bps.go.id/en/statistics-table/3/VUZwV01tSlpPVlpsWlRKbmMxcFhhSGhEVjFoUFFUMDkjMw%3D%3D/luas-daerah-dan-jumlah-pulau-menurut-kabupaten-kota-di-provinsi-jawa-timur--2024.html
A11: georgetown | B11: Secondary | C11: George Town, Penang (Wikipedia; 2020 population and area) | D11: https://en.wikipedia.org/wiki/George_Town,_Penang
A12: ipoh | B12: Secondary | C12: Ipoh (Wikipedia; 2020 population and area) | D12: https://en.wikipedia.org/wiki/Ipoh
... A34: hcmc_gdp | B34: Secondary | C34: HCMC leads Vietnam in economic output ahead of administrative changes - VietNamNet | D34: https://vietnamnet.vn/en/hcm-city-leads-vietnam-in-economic-output-ahead-of-administrative-changes-2387480.html

Sheet Sheet3
A1: Country name | B1: city name | C1: Population | D1: Population density | E1: administrative area | F1: GDP per capita（2024/$ | G1: Total GDP（2024） | H1: GRDP / PDRB (2024) | I1: Vehicle quantity | J1: motor vehicles per 1,000 people | K1: Road network supply | L1: road length | M1: Population density (persons/km)
A2: Philippines | B2: Manila | C2: 1902590 | D2: 44936 | E2: 42.34 | F2: 10800 | G2: $21.3 B | H2: 21.25 | I2: ~680,000 | J2: 357 | K2: 26.45 | L2: 1128.5 | M2: 44936
